Workbook

Sheet Read Me
B1: Thomson Reserve: Indicative Price Matrix v4 (All 1,268 Units)
B2: Built on the developer starting prices (latest Price Estimation Matrix) and the project chief floor guide (19 Oct 2026). Indicative only, not developer pricing.
B3: Created by Tricia Ong & Angus Lim
B5: Anchor: developer start | C5: The developer "starting from" PSF is the hard floor for every size: the cheapest stack on its lowest floor shows the developer quoted price exactly. Sizes without a confirmed starting price (775, 1,152, 1,367, 1,485, 1,808 sqft) start at the lowest PSF row the matrix offers.
B6: Project chief floor guide | C6: The guide gives the average PSF per floor band (e.g. Classic L2-7 from $2,700, L8-15 $2,800 to $2,900, L16-21 $3,000). The model draws a smooth floor curve through those averages, so prices climb floor by floor with no band jumps. Summary shows guide vs model for every band.
B7: Tiers A to E | C7: Each stack has a tier that sets its base position: A trophy, B inner pool facing / long pool vistas (pool facing commands a premium), C road-side or west-sun stacks with landed / nature views, D drop-off / road / boundary, E HDB / Thomson Three facing. On top of the tier, each stack carries its own mid and high-floor view loading. So Stack 01 is tier C (below pool-facing 06/18, tier B) on low floors, but its unblocked landed, nature reserve and city views load in on the way up, and its high floors price above 06/18. Stacks are ordered by our own tiers and stack calls (the slide numbering is not used).
B8: Stack position (+/- $50K) | C8: The guide is an average. Around it, each stack sits from about $50K below (most inferior) to about $50K above (best) on the same floor, ordered by our own tiers and stack calls. Unblocked nature reserve, landed, city and reservoir views carry the strongest mid and high-floor positions. A stack whose view opens up moves into its better position gradually over the floors before its view clears, so no single floor carries a big jump.
B9: Luxury always dearer | C9: On every floor, the cheapest Luxury unit (Blocks 5 and 7) is priced above the dearest Classic unit of the same size. Where the guide average alone would not achieve this, the Luxury curve carries an uplift, so Luxury averages for those sizes run above the guide.
B10: No dips | C10: No unit is priced below the floor beneath it in the same stack.
B11: Blocked views and parallax | C11: Stacks whose living-room view has a clubhouse, lounge or pavilion in the foreground (front edge within 40m, 3D site model). Clear floor allows for parallax: eye height needed = roof top + 1.6 / (3 + 2) x (front-edge distance + 5). Stacks 37, 50 and 51 load their premium fully by L10.
B12: Facing (compass) | C12: True compass facing of each stack from the 3D site model: e.g. 14/15/37 face WNW (west sun), 27 and 33 to 35 face SE (no afternoon sun), 19 to 22, 28, 36 and 52 to 55 face SW, 10 to 13 and 42 to 45 face SSW, 01 to 05 face SSE.
B13: Tabs | C13: Summary (checks, price ranges, guide vs model) · All Units (one row per unit with the price build-up) · 2BR ... 5BR matrices (A. price, B. PSF) · Developer Matrix · Assumptions (all inputs).
B14: Unit numbering | C14: #Floor-Stack, e.g. #05-19 is Level 5, Stack 19 (Block 5).
B15: Colour legend | C15: Yellow fill + blue text = input. Green text = pulled from Assumptions. Black = formula. Beige = Classic Collection, light blue = Luxury Collection.
B16: Disclaimer | C16: Estimates for client discussion only. Not the developer's official price list; actual prices may differ by stack and floor.

Sheet Summary
A1: Thomson Reserve: Model checks and price ranges
A2: Lowest model price must equal the developer "starting from". Floor bands and band averages follow the project chief floor guide (table at the bottom). Luxury is always priced above Classic of the same size on the same floor.
A3: ="Stack spread: +/- "&TEXT(Assumptions!$C$5,"$#,##0")&" around the floor average | Luxury lead over Classic, same floor: at least "&TEXT(Assumptions!$C$6,"$#,##0")&" psf" -> Stack spread: +/- $50,000 around the floor average | Luxury lead over Classic, same floor: at least $20 psf
A5: Size (sqft) | B5: Unit type | C5: Units | D5: Dev "starting from" | E5: Model lowest price | F5: Starting matches? | G5: Classic: model PSF range | H5: Developer top PSF (Classic) | I5: Luxury: model PSF range | J5: Developer top PSF (Luxury) | K5: Model highest price | L5: Luxury above Classic on every floor?
A6: 592 | B6: 2 Bedroom | C6: =COUNTIFS('All Units'!$G$5:$G$1272,A6) -> 100 | D6: =IF(Assumptions!$C$26="","not confirmed",Assumptions!$C$26) -> 1544000 | E6: =_xlfn.MINIFS('All Units'!$R$5:$R$1272,'All Units'!$G$5:$G$1272,A6) -> 1544000 | F6: =IF(_xlfn.MINIFS('All Units'!$Q$5:$Q$1272,'All Units'!$G$5:$G$1272,A6)<>Assumptions!$E$26,"CHECK",IF(ISNUMBER(D6),IF(E6=D6,"Yes","CHECK"),"Yes (PSF)")) -> Yes | G6: =IF(COUNTIFS('All Units'!$G$5:$G$1272,A6,'All Units'!$H$5:$H$1272,"Classic")=0,"-",TEXT(_xlfn.MINIFS('All Units'!$Q$5:$Q$1272,'All Units'!$G$5:$G$1272,A6,'All Units'!$H$5:$H$1272,"Classic"),"$#,##0")&" to "&TEXT(_xlfn.MAXIFS('All Units'!$Q$5:$Q$1272,'All Units'!$G$5:$G$1272,A6,'All Units'!$H$5:$H$1272,"Classic"),"$#,##0")) -> $2,608 to $3,171 | H6: =IF(Assumptions!$H$26="","-",Assumptions!$H$26) -> 3000 | I6: =IF(COUNTIFS('All Units'!$G$5:$G$1272,A6,'All Units'!$H$5:$H$1272,"Luxury")=0,"-",TEXT(_xlfn.MINIFS('All Units'!$Q$5:$Q$1272,'All Units'!$G$5:$G$1272,A6,'All Units'!$H$5:$H$1272,"Luxury"),"$#,##0")&" to "&TEXT(_xlfn.MAXIFS('All Units'!$Q$5:$Q$1272,'All Units'!$G$5:$G$1272,A6,'All Units'!$H$5:$H$1272,"Luxury"),"$#,##0")) -> - | J6: =IF(Assumptions!$I$26="","-",Assumptions!$I$26) -> - | K6: =_xlfn.MAXIFS('All Units'!$R$5:$R$1272,'All Units'!$G$5:$G$1272,A6) -> 1877200 | L6: n/a
A7: 678 | B7: 2 Bedroom Premium | C7: =COUNTIFS('All Units'!$G$5:$G$1272,A7) -> 416 | D7: =IF(Assumptions!$C$27="","not confirmed",Assumptions!$C$27) -> 1772000 | E7: =_xlfn.MINIFS('All Units'!$R$5:$R$1272,'All Units'!$G$5:$G$1272,A7) -> 1772000 | F7: =IF(_xlfn.MINIFS('All Units'!$Q$5:$Q$1272,'All Units'!$G$5:$G$1272,A7)<>Assumptions!$E$27,"CHECK",IF(ISNUMBER(D7),IF(E7=D7,"Yes","CHECK"),"Yes (PSF)")) -> Yes | G7: =IF(COUNTIFS('All Units'!$G$5:$G$1272,A7,'All Units'!$H$5:$H$1272,"Classic")=0,"-",TEXT(_xlfn.MINIFS('All Units'!$Q$5:$Q$1272,'All Units'!$G$5:$G$1272,A7,'All Units'!$H$5:$H$1272,"Classic"),"$#,##0")&" to "&TEXT(_xlfn.MAXIFS('All Units'!$Q$5:$Q$1272,'All Units'!$G$5:$G$1272,A7,'All Units'!$H$5:$H$1272,"Classic"),"$#,##0")) -> $2,613 to $3,125 | H7: =IF(Assumptions!$H$27="","-",Assumptions!$H$27) -> 2900 | I7: =IF(COUNTIFS('All Units'!$G$5:$G$1272,A7,'All Units'!$H$5:$H$1272,"Luxury")=0,"-",TEXT(_xlfn.MINIFS('All Units'!$Q$5:$Q$1272,'All Units'!$G$5:$G$1272,A7,'All Units'!$H$5:$H$1272,"Luxury"),"$#,##0")&" to "&TEXT(_xlfn.MAXIFS('All Units'!$Q$5:$Q$1272,'All Units'!$G$5:$G$1272,A7,'All Units'!$H$5:$H$1272,"Luxury"),"$#,##0")) -> $2,762 to $3,408 | J7: =IF(Assumptions!$I$27="","-",Assumptions!$I$27) -> 3100 | K7: =_xlfn.MAXIFS('All Units'!$R$5:$R$1272,'All Units'!$G$5:$G$1272,A7) -> 2310600 | L7: =IF(COUNTIF(Assumptions!$B$94:$B$123,"CHECK")=0,"Yes","CHECK") -> Yes
A8: 732 | B8: 2 Bedroom Premium + Study | C8: =COUNTIFS('All Units'!$G$5:$G$1272,A8) -> 120 | D8: =IF(Assumptions!$C$28="","not confirmed",Assumptions!$C$28) -> 1925000 | E8: =_xlfn.MINIFS('All Units'!$R$5:$R$1272,'All Units'!$G$5:$G$1272,A8) -> 1925000 | F8: =IF(_xlfn.MINIFS('All Units'!$Q$5:$Q$1272,'All Units'!$G$5:$G$1272,A8)<>Assumptions!$E$28,"CHECK",IF(ISNUMBER(D8),IF(E8=D8,"Yes","CHECK"),"Yes (PSF)")) -> Yes | G8: =IF(COUNTIFS('All Units'!$G$5:$G$1272,A8,'All Units'!$H$5:$H$1272,"Classic")=0,"-",TEXT(_xlfn.MINIFS('All Units'!$Q$5:$Q$1272,'All Units'!$G$5:$G$1272,A8,'All Units'!$H$5:$H$1272,"Classic"),"$#,##0")&" to "&TEXT(_xlfn.MAXIFS('All Units'!$Q$5:$Q$1272,'All Units'!$G$5:$G$1272,A8,'All Units'!$H$5:$H$1272,"Classic"),"$#,##0")) -> $2,630 to $3,149 | H8: =IF(Assumptions!$H$28="","-",Assumptions!$H$28) -> 2900 | I8: =IF(COUNTIFS('All Units'!$G$5:$G$1272,A8,'All Units'!$H$5:$H$1272,"Luxury")=0,"-",TEXT(_xlfn.MINIFS('All Units'!$Q$5:$Q$1272,'All Units'!$G$5:$G$1272,A8,'All Units'!$H$5:$H$1272,"Luxury"),"$#,##0")&" to "&TEXT(_xlfn.MAXIFS('All Units'!$Q$5:$Q$1272,'All Units'!$G$5:$G$1272,A8,'All Units'!$H$5:$H$1272,"Luxury"),"$#,##0")) -> $2,773 to $3,389 | J8: =IF(Assumptions!$I$28="","-",Assumptions!$I$28) -> 3100 | K8: =_xlfn.MAXIFS('All Units'!$R$5:$R$1272,'All Units'!$G$5:$G$1272,A8) -> 2480700 | L8: =IF(COUNTIF(Assumptions!$C$94:$C$123,"CHECK")=0,"Yes","CHECK") -> Yes
A9: 775 | B9: 2 Bedroom Premium + Study | C9: =COUNTIFS('All Units'!$G$5:$G$1272,A9) -> 80 | D9: =IF(Assumptions!$C$29="","not confirmed",Assumptions!$C$29) -> not confirmed | E9: =_xlfn.MINIFS('All Units'!$R$5:$R$1272,'All Units'!$G$5:$G$1272,A9) -> 2053800 | F9: =IF(_xlfn.MINIFS('All Units'!$Q$5:$Q$1272,'All Units'!$G$5:$G$1272,A9)<>Assumptions!$E$29,"CHECK",IF(ISNUMBER(D9),IF(E9=D9,"Yes","CHECK"),"Yes (PSF)")) -> Yes (PSF) | G9: =IF(COUNTIFS('All Units'!$G$5:$G$1272,A9,'All Units'!$H$5:$H$1272,"Classic")=0,"-",TEXT(_xlfn.MINIFS('All Units'!$Q$5:$Q$1272,'All Units'!$G$5:$G$1272,A9,'All Units'!$H$5:$H$1272,"Classic"),"$#,##0")&" to "&TEXT(_xlfn.MAXIFS('All Units'!$Q$5:$Q$1272,'All Units'!$G$5:$G$1272,A9,'All Units'!$H$5:$H$1272,"Classic"),"$#,##0")) -> $2,650 to $3,054 | H9: =IF(Assumptions!$H$29="","-",Assumptions!$H$29) -> 2900 | I9: =IF(COUNTIFS('All Units'!$G$5:$G$1272,A9,'All Units'!$H$5:$H$1272,"Luxury")=0,"-",TEXT(_xlfn.MINIFS('All Units'!$Q$5:$Q$1272,'All Units'!$G$5:$G$1272,A9,'All Units'!$H$5:$H$1272,"Luxury"),"$#,##0")&" to "&TEXT(_xlfn.MAXIFS('All Units'!$Q$5:$Q$1272,'All Units'!$G$5:$G$1272,A9,'All Units'!$H$5:$H$1272,"Luxury"),"$#,##0")) -> $2,693 to $3,298 | J9: =IF(Assumptions!$I$29="","-",Assumptions!$I$29) -> 3100 | K9: =_xlfn.MAXIFS('All Units'!$R$5:$R$1272,'All Units'!$G$5:$G$1272,A9) -> 2556000 | L9: =IF(COUNTIF(Assumptions!$D$94:$D$123,"CHECK")=0,"Yes","CHECK") -> Yes
A10: 947 | B10: 3 Bedroom | C10: =COUNTIFS('All Units'!$G$5:$G$1272,A10) -> 120 | D10: =IF(Assumptions!$C$30="","not confirmed",Assumptions!$C$30) -> 2503000 | E10: =_xlfn.MINIFS('All Units'!$R$5:$R$1272,'All Units'!$G$5:$G$1272,A10) -> 2503000 | F10: =IF(_xlfn.MINIFS('All Units'!$Q$5:$Q$1272,'All Units'!$G$5:$G$1272,A10)<>Assumptions!$E$30,"CHECK",IF(ISNUMBER(D10),IF(E10=D10,"Yes","CHECK"),"Yes (PSF)")) -> Yes | G10: =IF(COUNTIFS('All Units'!$G$5:$G$1272,A10,'All Units'!$H$5:$H$1272,"Classic")=0,"-",TEXT(_xlfn.MINIFS('All Units'!$Q$5:$Q$1272,'All Units'!$G$5:$G$1272,A10,'All Units'!$H$5:$H$1272,"Classic"),"$#,##0")&" to "&TEXT(_xlfn.MAXIFS('All Units'!$Q$5:$Q$1272,'All Units'!$G$5:$G$1272,A10,'All Units'!$H$5:$H$1272,"Classic"),"$#,##0")) -> $2,642 to $3,118 | H10: =IF(Assumptions!$H$30="","-",Assumptions!$H$30) -> 3000 | I10: =IF(COUNTIFS('All Units'!$G$5:$G$1272,A10,'All Units'!$H$5:$H$1272,"Luxury")=0,"-",TEXT(_xlfn.MINIFS('All Units'!$Q$5:$Q$1272,'All Units'!$G$5:$G$1272,A10,'All Units'!$H$5:$H$1272,"Luxury"),"$#,##0")&" to "&TEXT(_xlfn.MAXIFS('All Units'!$Q$5:$Q$1272,'All Units'!$G$5:$G$1272,A10,'All Units'!$H$5:$H$1272,"Luxury"),"$#,##0")) -> $2,743 to $3,281 | J10: =IF(Assumptions!$I$30="","-",Assumptions!$I$30) -> 3200 | K10: =_xlfn.MAXIFS('All Units'!$R$5:$R$1272,'All Units'!$G$5:$G$1272,A10) -> 3107100 | L10: =IF(COUNTIF(Assumptions!$E$94:$E$123,"CHECK")=0,"Yes","CHECK") -> Yes
A11: 1055 | B11: 3 Bedroom Premium | C11: =COUNTIFS('All Units'!$G$5:$G$1272,A11) -> 170 | D11: =IF(Assumptions!$C$31="","not confirmed",Assumptions!$C$31) -> 2777000 | E11: =_xlfn.MINIFS('All Units'!$R$5:$R$1272,'All Units'!$G$5:$G$1272,A11) -> 2777000 | F11: =IF(_xlfn.MINIFS('All Units'!$Q$5:$Q$1272,'All Units'!$G$5:$G$1272,A11)<>Assumptions!$E$31,"CHECK",IF(ISNUMBER(D11),IF(E11=D11,"Yes","CHECK"),"Yes (PSF)")) -> Yes | G11: =IF(COUNTIFS('All Units'!$G$5:$G$1272,A11,'All Units'!$H$5:$H$1272,"Classic")=0,"-",TEXT(_xlfn.MINIFS('All Units'!$Q$5:$Q$1272,'All Units'!$G$5:$G$1272,A11,'All Units'!$H$5:$H$1272,"Classic"),"$#,##0")&" to "&TEXT(_xlfn.MAXIFS('All Units'!$Q$5:$Q$1272,'All Units'!$G$5:$G$1272,A11,'All Units'!$H$5:$H$1272,"Classic"),"$#,##0")) -> $2,633 to $3,090 | H11: =IF(Assumptions!$H$31="","-",Assumptions!$H$31) -> 3000 | I11: =IF(COUNTIFS('All Units'!$G$5:$G$1272,A11,'All Units'!$H$5:$H$1272,"Luxury")=0,"-",TEXT(_xlfn.MINIFS('All Units'!$Q$5:$Q$1272,'All Units'!$G$5:$G$1272,A11,'All Units'!$H$5:$H$1272,"Luxury"),"$#,##0")&" to "&TEXT(_xlfn.MAXIFS('All Units'!$Q$5:$Q$1272,'All Units'!$G$5:$G$1272,A11,'All Units'!$H$5:$H$1272,"Luxury"),"$#,##0")) -> $2,776 to $3,254 | J11: =IF(Assumptions!$I$31="","-",Assumptions!$I$31) -> 3200 | K11: =_xlfn.MAXIFS('All Units'!$R$5:$R$1272,'All Units'!$G$5:$G$1272,A11) -> 3433000 | L11: =IF(COUNTIF(Assumptions!$F$94:$F$123,"CHECK")=0,"Yes","CHECK") -> Yes
A12: 1152 | B12: 3 Bedroom Premium + Study | C12: =COUNTIFS('All Units'!$G$5:$G$1272,A12) -> 60 | D12: =IF(Assumptions!$C$32="","not confirmed",Assumptions!$C$32) -> not confirmed | E12: =_xlfn.MINIFS('All Units'!$R$5:$R$1272,'All Units'!$G$5:$G$1272,A12) -> 3052800 | F12: =IF(_xlfn.MINIFS('All Units'!$Q$5:$Q$1272,'All Units'!$G$5:$G$1272,A12)<>Assumptions!$E$32,"CHECK",IF(ISNUMBER(D12),IF(E12=D12,"Yes","CHECK"),"Yes (PSF)")) -> Yes (PSF) | G12: =IF(COUNTIFS('All Units'!$G$5:$G$1272,A12,'All Units'!$H$5:$H$1272,"Classic")=0,"-",TEXT(_xlfn.MINIFS('All Units'!$Q$5:$Q$1272,'All Units'!$G$5:$G$1272,A12,'All Units'!$H$5:$H$1272,"Classic"),"$#,##0")&" to "&TEXT(_xlfn.MAXIFS('All Units'!$Q$5:$Q$1272,'All Units'!$G$5:$G$1272,A12,'All Units'!$H$5:$H$1272,"Classic"),"$#,##0")) -> $2,650 to $3,092 | H12: =IF(Assumptions!$H$32="","-",Assumptions!$H$32) -> 3000 | I12: =IF(COUNTIFS('All Units'!$G$5:$G$1272,A12,'All Units'!$H$5:$H$1272,"Luxury")=0,"-",TEXT(_xlfn.MINIFS('All Units'!$Q$5:$Q$1272,'All Units'!$G$5:$G$1272,A12,'All Units'!$H$5:$H$1272,"Luxury"),"$#,##0")&" to "&TEXT(_xlfn.MAXIFS('All Units'!$Q$5:$Q$1272,'All Units'!$G$5:$G$1272,A12,'All Units'!$H$5:$H$1272,"Luxury"),"$#,##0")) -> - | J12: =IF(Assumptions!$I$32="","-",Assumptions!$I$32) -> - | K12: =_xlfn.MAXIFS('All Units'!$R$5:$R$1272,'All Units'!$G$5:$G$1272,A12) -> 3562000 | L12: n/a
A13: 1238 | B13: 4 Bedroom | C13: =COUNTIFS('All Units'!$G$5:$G$1272,A13) -> 90 | D13: =IF(Assumptions!$C$33="","not confirmed",Assumptions!$C$33) -> 3388000 | E13: =_xlfn.MINIFS('All Units'!$R$5:$R$1272,'All Units'!$G$5:$G$1272,A13) -> 3388000 | F13: =IF(_xlfn.MINIFS('All Units'!$Q$5:$Q$1272,'All Units'!$G$5:$G$1272,A13)<>Assumptions!$E$33,"CHECK",IF(ISNUMBER(D13),IF(E13=D13,"Yes","CHECK"),"Yes (PSF)")) -> Yes | G13: =IF(COUNTIFS('All Units'!$G$5:$G$1272,A13,'All Units'!$H$5:$H$1272,"Classic")=0,"-",TEXT(_xlfn.MINIFS('All Units'!$Q$5:$Q$1272,'All Units'!$G$5:$G$1272,A13,'All Units'!$H$5:$H$1272,"Classic"),"$#,##0")&" to "&TEXT(_xlfn.MAXIFS('All Units'!$Q$5:$Q$1272,'All Units'!$G$5:$G$1272,A13,'All Units'!$H$5:$H$1272,"Classic"),"$#,##0")) -> $2,737 to $3,113 | H13: =IF(Assumptions!$H$33="","-",Assumptions!$H$33) -> 3000 | I13: =IF(COUNTIFS('All Units'!$G$5:$G$1272,A13,'All Units'!$H$5:$H$1272,"Luxury")=0,"-",TEXT(_xlfn.MINIFS('All Units'!$Q$5:$Q$1272,'All Units'!$G$5:$G$1272,A13,'All Units'!$H$5:$H$1272,"Luxury"),"$#,##0")&" to "&TEXT(_xlfn.MAXIFS('All Units'!$Q$5:$Q$1272,'All Units'!$G$5:$G$1272,A13,'All Units'!$H$5:$H$1272,"Luxury"),"$#,##0")) -> $2,825 to $3,331 | J13: =IF(Assumptions!$I$33="","-",Assumptions!$I$33) -> 3200 | K13: =_xlfn.MAXIFS('All Units'!$R$5:$R$1272,'All Units'!$G$5:$G$1272,A13) -> 4123800 | L13: =IF(COUNTIF(Assumptions!$G$94:$G$123,"CHECK")=0,"Yes","CHECK") -> Yes
A14: 1367 | B14: 4 Bedroom Premium (w Private Lift) | C14: =COUNTIFS('All Units'!$G$5:$G$1272,A14) -> 56 | D14: =IF(Assumptions!$C$34="","not confirmed",Assumptions!$C$34) -> not confirmed | E14: =_xlfn.MINIFS('All Units'!$R$5:$R$1272,'All Units'!$G$5:$G$1272,A14) -> 3827600 | F14: =IF(_xlfn.MINIFS('All Units'!$Q$5:$Q$1272,'All Units'!$G$5:$G$1272,A14)<>Assumptions!$E$34,"CHECK",IF(ISNUMBER(D14),IF(E14=D14,"Yes","CHECK"),"Yes (PSF)")) -> Yes (PSF) | G14: =IF(COUNTIFS('All Units'!$G$5:$G$1272,A14,'All Units'!$H$5:$H$1272,"Classic")=0,"-",TEXT(_xlfn.MINIFS('All Units'!$Q$5:$Q$1272,'All Units'!$G$5:$G$1272,A14,'All Units'!$H$5:$H$1272,"Classic"),"$#,##0")&" to "&TEXT(_xlfn.MAXIFS('All Units'!$Q$5:$Q$1272,'All Units'!$G$5:$G$1272,A14,'All Units'!$H$5:$H$1272,"Classic"),"$#,##0")) -> - | H14: =IF(Assumptions!$H$34="","-",Assumptions!$H$34) -> - | I14: =IF(COUNTIFS('All Units'!$G$5:$G$1272,A14,'All Units'!$H$5:$H$1272,"Luxury")=0,"-",TEXT(_xlfn.MINIFS('All Units'!$Q$5:$Q$1272,'All Units'!$G$5:$G$1272,A14,'All Units'!$H$5:$H$1272,"Luxury"),"$#,##0")&" to "&TEXT(_xlfn.MAXIFS('All Units'!$Q$5:$Q$1272,'All Units'!$G$5:$G$1272,A14,'All Units'!$H$5:$H$1272,"Luxury"),"$#,##0")) -> $2,800 to $3,356 | J14: =IF(Assumptions!$I$34="","-",Assumptions!$I$34) -> 3300 | K14: =_xlfn.MAXIFS('All Units'!$R$5:$R$1272,'All Units'!$G$5:$G$1272,A14) -> 4587700 | L14: n/a
A15: 1485 | B15: 4 Bedroom Premium + Study (w Private Lift) | C15: =COUNTIFS('All Units'!$G$5:$G$1272,A15) -> 28 | D15: =IF(Assumptions!$C$35="","not confirmed",Assumptions!$C$35) -> not confirmed | E15: =_xlfn.MINIFS('All Units'!$R$5:$R$1272,'All Units'!$G$5:$G$1272,A15) -> 4158000 | F15: =IF(_xlfn.MINIFS('All Units'!$Q$5:$Q$1272,'All Units'!$G$5:$G$1272,A15)<>Assumptions!$E$35,"CHECK",IF(ISNUMBER(D15),IF(E15=D15,"Yes","CHECK"),"Yes (PSF)")) -> Yes (PSF) | G15: =IF(COUNTIFS('All Units'!$G$5:$G$1272,A15,'All Units'!$H$5:$H$1272,"Classic")=0,"-",TEXT(_xlfn.MINIFS('All Units'!$Q$5:$Q$1272,'All Units'!$G$5:$G$1272,A15,'All Units'!$H$5:$H$1272,"Classic"),"$#,##0")&" to "&TEXT(_xlfn.MAXIFS('All Units'!$Q$5:$Q$1272,'All Units'!$G$5:$G$1272,A15,'All Units'!$H$5:$H$1272,"Classic"),"$#,##0")) -> - | H15: =IF(Assumptions!$H$35="","-",Assumptions!$H$35) -> - | I15: =IF(COUNTIFS('All Units'!$G$5:$G$1272,A15,'All Units'!$H$5:$H$1272,"Luxury")=0,"-",TEXT(_xlfn.MINIFS('All Units'!$Q$5:$Q$1272,'All Units'!$G$5:$G$1272,A15,'All Units'!$H$5:$H$1272,"Luxury"),"$#,##0")&" to "&TEXT(_xlfn.MAXIFS('All Units'!$Q$5:$Q$1272,'All Units'!$G$5:$G$1272,A15,'All Units'!$H$5:$H$1272,"Luxury"),"$#,##0")) -> $2,800 to $3,328 | J15: =IF(Assumptions!$I$35="","-",Assumptions!$I$35) -> 3300 | K15: =_xlfn.MAXIFS('All Units'!$R$5:$R$1272,'All Units'!$G$5:$G$1272,A15) -> 4942100 | L15: n/a
A16: 1808 | B16: 5 Bedroom Suite (w Private Lift) | C16: =COUNTIFS('All Units'!$G$5:$G$1272,A16) -> 28 | D16: =IF(Assumptions!$C$36="","not confirmed",Assumptions!$C$36) -> not confirmed | E16: =_xlfn.MINIFS('All Units'!$R$5:$R$1272,'All Units'!$G$5:$G$1272,A16) -> 5062400 | F16: =IF(_xlfn.MINIFS('All Units'!$Q$5:$Q$1272,'All Units'!$G$5:$G$1272,A16)<>Assumptions!$E$36,"CHECK",IF(ISNUMBER(D16),IF(E16=D16,"Yes","CHECK"),"Yes (PSF)")) -> Yes (PSF) | G16: =IF(COUNTIFS('All Units'!$G$5:$G$1272,A16,'All Units'!$H$5:$H$1272,"Classic")=0,"-",TEXT(_xlfn.MINIFS('All Units'!$Q$5:$Q$1272,'All Units'!$G$5:$G$1272,A16,'All Units'!$H$5:$H$1272,"Classic"),"$#,##0")&" to "&TEXT(_xlfn.MAXIFS('All Units'!$Q$5:$Q$1272,'All Units'!$G$5:$G$1272,A16,'All Units'!$H$5:$H$1272,"Classic"),"$#,##0")) -> - | H16: =IF(Assumptions!$H$36="","-",Assumptions!$H$36) -> - | I16: =IF(COUNTIFS('All Units'!$G$5:$G$1272,A16,'All Units'!$H$5:$H$1272,"Luxury")=0,"-",TEXT(_xlfn.MINIFS('All Units'!$Q$5:$Q$1272,'All Units'!$G$5:$G$1272,A16,'All Units'!$H$5:$H$1272,"Luxury"),"$#,##0")&" to "&TEXT(_xlfn.MAXIFS('All Units'!$Q$5:$Q$1272,'All Units'!$G$5:$G$1272,A16,'All Units'!$H$5:$H$1272,"Luxury"),"$#,##0")) -> $2,800 to $3,328 | J16: =IF(Assumptions!$I$36="","-",Assumptions!$I$36) -> 3300 | K16: =_xlfn.MAXIFS('All Units'!$R$5:$R$1272,'All Units'!$G$5:$G$1272,A16) -> 6017000 | L16: n/a
A17: Total | C17: =SUM(C6:C16) -> 1268
A19: Price range by unit type, collection and floor band (unit counts checked against the developer unit mix)
A20: Unit type | B20: Size (sqft) | C20: Collection | D20: Units | E20: Low floors | F20: Mid floors | G20: High floors | H20: Lowest | I20: Highest | J20: Developer unit mix | K20: Matches?
A21: 2 Bedroom | B21: 592 | C21: Classic | D21: =COUNTIFS('All Units'!$G$5:$G$1272,$B21,'All Units'!$H$5:$H$1272,$C21) -> 100 | E21: =IF(COUNTIFS('All Units'!$G$5:$G$1272,$B21,'All Units'!$H$5:$H$1272,$C21,'All Units'!$J$5:$J$1272,"Low")=0,"-",TEXT(_xlfn.MINIFS('All Units'!$R$5:$R$1272,'All Units'!$G$5:$G$1272,$B21,'All Units'!$H$5:$H$1272,$C21,'All Units'!$J$5:$J$1272,"Low")/1000000,"$0.000")&"M to "&TEXT(_xlfn.MAXIFS('All Units'!$R$5:$R$1272,'All Units'!$G$5:$G$1272,$B21,'All Units'!$H$5:$H$1272,$C21,'All Units'!$J$5:$J$1272,"Low")/1000000,"$0.000")&"M") -> $1.544M to $1.701M | F21: =IF(COUNTIFS('All Units'!$G$5:$G$1272,$B21,'All Units'!$H$5:$H$1272,$C21,'All Units'!$J$5:$J$1272,"Mid")=0,"-",TEXT(_xlfn.MINIFS('All Units'!$R$5:$R$1272,'All Units'!$G$5:$G$1272,$B21,'All Units'!$H$5:$H$1272,$C21,'All Units'!$J$5:$J$1272,"Mid")/1000000,"$0.000")&"M to "&TEXT(_xlfn.MAXIFS('All Units'!$R$5:$R$1272,'All Units'!$G$5:$G$1272,$B21,'All Units'!$H$5:$H$1272,$C21,'All Units'!$J$5:$J$1272,"Mid")/1000000,"$0.000")&"M") -> $1.613M to $1.799M | G21: =IF(COUNTIFS('All Units'!$G$5:$G$1272,$B21,'All Units'!$H$5:$H$1272,$C21,'All Units'!$J$5:$J$1272,"High")=0,"-",TEXT(_xlfn.MINIFS('All Units'!$R$5:$R$1272,'All Units'!$G$5:$G$1272,$B21,'All Units'!$H$5:$H$1272,$C21,'All Units'!$J$5:$J$1272,"High")/1000000,"$0.000")&"M to "&TEXT(_xlfn.MAXIFS('All Units'!$R$5:$R$1272,'All Units'!$G$5:$G$1272,$B21,'All Units'!$H$5:$H$1272,$C21,'All Units'!$J$5:$J$1272,"High")/1000000,"$0.000")&"M") -> $1.712M to $1.877M | H21: =_xlfn.MINIFS('All Units'!$R$5:$R$1272,'All Units'!$G$5:$G$1272,$B21,'All Units'!$H$5:$H$1272,$C21) -> 1544000 | I21: =_xlfn.MAXIFS('All Units'!$R$5:$R$1272,'All Units'!$G$5:$G$1272,$B21,'All Units'!$H$5:$H$1272,$C21) -> 1877200
A22: Total 2 Bedroom | B22: 592 | D22: =SUM(D21:D21) -> 100 | H22: =MIN(H21:H21) -> 1544000 | I22: =MAX(I21:I21) -> 1877200 | J22: 100 | K22: =IF(D22=J22,"Yes","CHECK") -> Yes
A23: 2 Bedroom Premium | B23: 678 | C23: Classic | D23: =COUNTIFS('All Units'!$G$5:$G$1272,$B23,'All Units'!$H$5:$H$1272,$C23) -> 240 | E23: =IF(COUNTIFS('All Units'!$G$5:$G$1272,$B23,'All Units'!$H$5:$H$1272,$C23,'All Units'!$J$5:$J$1272,"Low")=0,"-",TEXT(_xlfn.MINIFS('All Units'!$R$5:$R$1272,'All Units'!$G$5:$G$1272,$B23,'All Units'!$H$5:$H$1272,$C23,'All Units'!$J$5:$J$1272,"Low")/1000000,"$0.000")&"M to "&TEXT(_xlfn.MAXIFS('All Units'!$R$5:$R$1272,'All Units'!$G$5:$G$1272,$B23,'All Units'!$H$5:$H$1272,$C23,'All Units'!$J$5:$J$1272,"Low")/1000000,"$0.000")&"M") -> $1.772M to $1.924M | F23: =IF(COUNTIFS('All Units'!$G$5:$G$1272,$B23,'All Units'!$H$5:$H$1272,$C23,'All Units'!$J$5:$J$1272,"Mid")=0,"-",TEXT(_xlfn.MINIFS('All Units'!$R$5:$R$1272,'All Units'!$G$5:$G$1272,$B23,'All Units'!$H$5:$H$1272,$C23,'All Units'!$J$5:$J$1272,"Mid")/1000000,"$0.000")&"M to "&TEXT(_xlfn.MAXIFS('All Units'!$R$5:$R$1272,'All Units'!$G$5:$G$1272,$B23,'All Units'!$H$5:$H$1272,$C23,'All Units'!$J$5:$J$1272,"Mid")/1000000,"$0.000")&"M") -> $1.835M to $2.026M | G23: =IF(COUNTIFS('All Units'!$G$5:$G$1272,$B23,'All Units'!$H$5:$H$1272,$C23,'All Units'!$J$5:$J$1272,"High")=0,"-",TEXT(_xlfn.MINIFS('All Units'!$R$5:$R$1272,'All Units'!$G$5:$G$1272,$B23,'All Units'!$H$5:$H$1272,$C23,'All Units'!$J$5:$J$1272,"High")/1000000,"$0.000")&"M to "&TEXT(_xlfn.MAXIFS('All Units'!$R$5:$R$1272,'All Units'!$G$5:$G$1272,$B23,'All Units'!$H$5:$H$1272,$C23,'All Units'!$J$5:$J$1272,"High")/1000000,"$0.000")&"M") -> $1.941M to $2.119M | H23: =_xlfn.MINIFS('All Units'!$R$5:$R$1272,'All Units'!$G$5:$G$1272,$B23,'All Units'!$H$5:$H$1272,$C23) -> 1772000 | I23: =_xlfn.MAXIFS('All Units'!$R$5:$R$1272,'All Units'!$G$5:$G$1272,$B23,'All Units'!$H$5:$H$1272,$C23) -> 2118800
A24: 2 Bedroom Premium | B24: 678 | C24: Luxury | D24: =COUNTIFS('All Units'!$G$5:$G$1272,$B24,'All Units'!$H$5:$H$1272,$C24) -> 176 | E24: =IF(COUNTIFS('All Units'!$G$5:$G$1272,$B24,'All Units'!$H$5:$H$1272,$C24,'All Units'!$J$5:$J$1272,"Low")=0,"-",TEXT(_xlfn.MINIFS('All Units'!$R$5:$R$1272,'All Units'!$G$5:$G$1272,$B24,'All Units'!$H$5:$H$1272,$C24,'All Units'!$J$5:$J$1272,"Low")/1000000,"$0.000")&"M to "&TEXT(_xlfn.MAXIFS('All Units'!$R$5:$R$1272,'All Units'!$G$5:$G$1272,$B24,'All Units'!$H$5:$H$1272,$C24,'All Units'!$J$5:$J$1272,"Low")/1000000,"$0.000")&"M") -> $1.873M to $2.142M | F24: =IF(COUNTIFS('All Units'!$G$5:$G$1272,$B24,'All Units'!$H$5:$H$1272,$C24,'All Units'!$J$5:$J$1272,"Mid")=0,"-",TEXT(_xlfn.MINIFS('All Units'!$R$5:$R$1272,'All Units'!$G$5:$G$1272,$B24,'All Units'!$H$5:$H$1272,$C24,'All Units'!$J$5:$J$1272,"Mid")/1000000,"$0.000")&"M to "&TEXT(_xlfn.MAXIFS('All Units'!$R$5:$R$1272,'All Units'!$G$5:$G$1272,$B24,'All Units'!$H$5:$H$1272,$C24,'All Units'!$J$5:$J$1272,"Mid")/1000000,"$0.000")&"M") -> $2.055M to $2.233M | G24: =IF(COUNTIFS('All Units'!$G$5:$G$1272,$B24,'All Units'!$H$5:$H$1272,$C24,'All Units'!$J$5:$J$1272,"High")=0,"-",TEXT(_xlfn.MINIFS('All Units'!$R$5:$R$1272,'All Units'!$G$5:$G$1272,$B24,'All Units'!$H$5:$H$1272,$C24,'All Units'!$J$5:$J$1272,"High")/1000000,"$0.000")&"M to "&TEXT(_xlfn.MAXIFS('All Units'!$R$5:$R$1272,'All Units'!$G$5:$G$1272,$B24,'All Units'!$H$5:$H$1272,$C24,'All Units'!$J$5:$J$1272,"High")/1000000,"$0.000")&"M") -> $2.141M to $2.311M | H24: =_xlfn.MINIFS('All Units'!$R$5:$R$1272,'All Units'!$G$5:$G$1272,$B24,'All Units'!$H$5:$H$1272,$C24) -> 1872600 | I24: =_xlfn.MAXIFS('All Units'!$R$5:$R$1272,'All Units'!$G$5:$G$1272,$B24,'All Units'!$H$5:$H$1272,$C24) -> 2310600
A25: Total 2 Bedroom Premium | B25: 678 | C25: Both | D25: =SUM(D23:D24) -> 416 | H25: =MIN(H23:H24) -> 1772000 | I25: =MAX(I23:I24) -> 2310600 | J25: 416 | K25: =IF(D25=J25,"Yes","CHECK") -> Yes
A26: 2 Bedroom Premium + Study | B26: 732 | C26: Classic | D26: =COUNTIFS('All Units'!$G$5:$G$1272,$B26,'All Units'!$H$5:$H$1272,$C26) -> 60 | E26: =IF(COUNTIFS('All Units'!$G$5:$G$1272,$B26,'All Units'!$H$5:$H$1272,$C26,'All Units'!$J$5:$J$1272,"Low")=0,"-",TEXT(_xlfn.MINIFS('All Units'!$R$5:$R$1272,'All Units'!$G$5:$G$1272,$B26,'All Units'!$H$5:$H$1272,$C26,'All Units'!$J$5:$J$1272,"Low")/1000000,"$0.000")&"M to "&TEXT(_xlfn.MAXIFS('All Units'!$R$5:$R$1272,'All Units'!$G$5:$G$1272,$B26,'All Units'!$H$5:$H$1272,$C26,'All Units'!$J$5:$J$1272,"Low")/1000000,"$0.000")&"M") -> $1.925M to $2.072M | F26: =IF(COUNTIFS('All Units'!$G$5:$G$1272,$B26,'All Units'!$H$5:$H$1272,$C26,'All Units'!$J$5:$J$1272,"Mid")=0,"-",TEXT(_xlfn.MINIFS('All Units'!$R$5:$R$1272,'All Units'!$G$5:$G$1272,$B26,'All Units'!$H$5:$H$1272,$C26,'All Units'!$J$5:$J$1272,"Mid")/1000000,"$0.000")&"M to "&TEXT(_xlfn.MAXIFS('All Units'!$R$5:$R$1272,'All Units'!$G$5:$G$1272,$B26,'All Units'!$H$5:$H$1272,$C26,'All Units'!$J$5:$J$1272,"Mid")/1000000,"$0.000")&"M") -> $2.023M to $2.203M | G26: =IF(COUNTIFS('All Units'!$G$5:$G$1272,$B26,'All Units'!$H$5:$H$1272,$C26,'All Units'!$J$5:$J$1272,"High")=0,"-",TEXT(_xlfn.MINIFS('All Units'!$R$5:$R$1272,'All Units'!$G$5:$G$1272,$B26,'All Units'!$H$5:$H$1272,$C26,'All Units'!$J$5:$J$1272,"High")/1000000,"$0.000")&"M to "&TEXT(_xlfn.MAXIFS('All Units'!$R$5:$R$1272,'All Units'!$G$5:$G$1272,$B26,'All Units'!$H$5:$H$1272,$C26,'All Units'!$J$5:$J$1272,"High")/1000000,"$0.000")&"M") -> $2.121M to $2.305M | H26: =_xlfn.MINIFS('All Units'!$R$5:$R$1272,'All Units'!$G$5:$G$1272,$B26,'All Units'!$H$5:$H$1272,$C26) -> 1925000 | I26: =_xlfn.MAXIFS('All Units'!$R$5:$R$1272,'All Units'!$G$5:$G$1272,$B26,'All Units'!$H$5:$H$1272,$C26) -> 2305100
A27: 2 Bedroom Premium + Study | B27: 732 | C27: Luxury | D27: =COUNTIFS('All Units'!$G$5:$G$1272,$B27,'All Units'!$H$5:$H$1272,$C27) -> 60 | E27: =IF(COUNTIFS('All Units'!$G$5:$G$1272,$B27,'All Units'!$H$5:$H$1272,$C27,'All Units'!$J$5:$J$1272,"Low")=0,"-",TEXT(_xlfn.MINIFS('All Units'!$R$5:$R$1272,'All Units'!$G$5:$G$1272,$B27,'All Units'!$H$5:$H$1272,$C27,'All Units'!$J$5:$J$1272,"Low")/1000000,"$0.000")&"M to "&TEXT(_xlfn.MAXIFS('All Units'!$R$5:$R$1272,'All Units'!$G$5:$G$1272,$B27,'All Units'!$H$5:$H$1272,$C27,'All Units'!$J$5:$J$1272,"Low")/1000000,"$0.000")&"M") -> $2.030M to $2.208M | F27: =IF(COUNTIFS('All Units'!$G$5:$G$1272,$B27,'All Units'!$H$5:$H$1272,$C27,'All Units'!$J$5:$J$1272,"Mid")=0,"-",TEXT(_xlfn.MINIFS('All Units'!$R$5:$R$1272,'All Units'!$G$5:$G$1272,$B27,'All Units'!$H$5:$H$1272,$C27,'All Units'!$J$5:$J$1272,"Mid")/1000000,"$0.000")&"M to "&TEXT(_xlfn.MAXIFS('All Units'!$R$5:$R$1272,'All Units'!$G$5:$G$1272,$B27,'All Units'!$H$5:$H$1272,$C27,'All Units'!$J$5:$J$1272,"Mid")/1000000,"$0.000")&"M") -> $2.209M to $2.407M | G27: =IF(COUNTIFS('All Units'!$G$5:$G$1272,$B27,'All Units'!$H$5:$H$1272,$C27,'All Units'!$J$5:$J$1272,"High")=0,"-",TEXT(_xlfn.MINIFS('All Units'!$R$5:$R$1272,'All Units'!$G$5:$G$1272,$B27,'All Units'!$H$5:$H$1272,$C27,'All Units'!$J$5:$J$1272,"High")/1000000,"$0.000")&"M to "&TEXT(_xlfn.MAXIFS('All Units'!$R$5:$R$1272,'All Units'!$G$5:$G$1272,$B27,'All Units'!$H$5:$H$1272,$C27,'All Units'!$J$5:$J$1272,"High")/1000000,"$0.000")&"M") -> $2.320M to $2.481M | H27: =_xlfn.MINIFS('All Units'!$R$5:$R$1272,'All Units'!$G$5:$G$1272,$B27,'All Units'!$H$5:$H$1272,$C27) -> 2029800 | I27: =_xlfn.MAXIFS('All Units'!$R$5:$R$1272,'All Units'!$G$5:$G$1272,$B27,'All Units'!$H$5:$H$1272,$C27) -> 2480700
A28: 2 Bedroom Premium + Study | B28: 775 | C28: Classic | D28: =COUNTIFS('All Units'!$G$5:$G$1272,$B28,'All Units'!$H$5:$H$1272,$C28) -> 20 | E28: =IF(COUNTIFS('All Units'!$G$5:$G$1272,$B28,'All Units'!$H$5:$H$1272,$C28,'All Units'!$J$5:$J$1272,"Low")=0,"-",TEXT(_xlfn.MINIFS('All Units'!$R$5:$R$1272,'All Units'!$G$5:$G$1272,$B28,'All Units'!$H$5:$H$1272,$C28,'All Units'!$J$5:$J$1272,"Low")/1000000,"$0.000")&"M to "&TEXT(_xlfn.MAXIFS('All Units'!$R$5:$R$1272,'All Units'!$G$5:$G$1272,$B28,'All Units'!$H$5:$H$1272,$C28,'All Units'!$J$5:$J$1272,"Low")/1000000,"$0.000")&"M") -> $2.054M to $2.135M | F28: =IF(COUNTIFS('All Units'!$G$5:$G$1272,$B28,'All Units'!$H$5:$H$1272,$C28,'All Units'!$J$5:$J$1272,"Mid")=0,"-",TEXT(_xlfn.MINIFS('All Units'!$R$5:$R$1272,'All Units'!$G$5:$G$1272,$B28,'All Units'!$H$5:$H$1272,$C28,'All Units'!$J$5:$J$1272,"Mid")/1000000,"$0.000")&"M to "&TEXT(_xlfn.MAXIFS('All Units'!$R$5:$R$1272,'All Units'!$G$5:$G$1272,$B28,'All Units'!$H$5:$H$1272,$C28,'All Units'!$J$5:$J$1272,"Mid")/1000000,"$0.000")&"M") -> $2.151M to $2.267M | G28: =IF(COUNTIFS('All Units'!$G$5:$G$1272,$B28,'All Units'!$H$5:$H$1272,$C28,'All Units'!$J$5:$J$1272,"High")=0,"-",TEXT(_xlfn.MINIFS('All Units'!$R$5:$R$1272,'All Units'!$G$5:$G$1272,$B28,'All Units'!$H$5:$H$1272,$C28,'All Units'!$J$5:$J$1272,"High")/1000000,"$0.000")&"M to "&TEXT(_xlfn.MAXIFS('All Units'!$R$5:$R$1272,'All Units'!$G$5:$G$1272,$B28,'All Units'!$H$5:$H$1272,$C28,'All Units'!$J$5:$J$1272,"High")/1000000,"$0.000")&"M") -> $2.283M to $2.367M | H28: =_xlfn.MINIFS('All Units'!$R$5:$R$1272,'All Units'!$G$5:$G$1272,$B28,'All Units'!$H$5:$H$1272,$C28) -> 2053800 | I28: =_xlfn.MAXIFS('All Units'!$R$5:$R$1272,'All Units'!$G$5:$G$1272,$B28,'All Units'!$H$5:$H$1272,$C28) -> 2366900
A29: 2 Bedroom Premium + Study | B29: 775 | C29: Luxury | D29: =COUNTIFS('All Units'!$G$5:$G$1272,$B29,'All Units'!$H$5:$H$1272,$C29) -> 60 | E29: =IF(COUNTIFS('All Units'!$G$5:$G$1272,$B29,'All Units'!$H$5:$H$1272,$C29,'All Units'!$J$5:$J$1272,"Low")=0,"-",TEXT(_xlfn.MINIFS('All Units'!$R$5:$R$1272,'All Units'!$G$5:$G$1272,$B29,'All Units'!$H$5:$H$1272,$C29,'All Units'!$J$5:$J$1272,"Low")/1000000,"$0.000")&"M to "&TEXT(_xlfn.MAXIFS('All Units'!$R$5:$R$1272,'All Units'!$G$5:$G$1272,$B29,'All Units'!$H$5:$H$1272,$C29,'All Units'!$J$5:$J$1272,"Low")/1000000,"$0.000")&"M") -> $2.087M to $2.289M | F29: =IF(COUNTIFS('All Units'!$G$5:$G$1272,$B29,'All Units'!$H$5:$H$1272,$C29,'All Units'!$J$5:$J$1272,"Mid")=0,"-",TEXT(_xlfn.MINIFS('All Units'!$R$5:$R$1272,'All Units'!$G$5:$G$1272,$B29,'All Units'!$H$5:$H$1272,$C29,'All Units'!$J$5:$J$1272,"Mid")/1000000,"$0.000")&"M to "&TEXT(_xlfn.MAXIFS('All Units'!$R$5:$R$1272,'All Units'!$G$5:$G$1272,$B29,'All Units'!$H$5:$H$1272,$C29,'All Units'!$J$5:$J$1272,"Mid")/1000000,"$0.000")&"M") -> $2.292M to $2.463M | G29: =IF(COUNTIFS('All Units'!$G$5:$G$1272,$B29,'All Units'!$H$5:$H$1272,$C29,'All Units'!$J$5:$J$1272,"High")=0,"-",TEXT(_xlfn.MINIFS('All Units'!$R$5:$R$1272,'All Units'!$G$5:$G$1272,$B29,'All Units'!$H$5:$H$1272,$C29,'All Units'!$J$5:$J$1272,"High")/1000000,"$0.000")&"M to "&TEXT(_xlfn.MAXIFS('All Units'!$R$5:$R$1272,'All Units'!$G$5:$G$1272,$B29,'All Units'!$H$5:$H$1272,$C29,'All Units'!$J$5:$J$1272,"High")/1000000,"$0.000")&"M") -> $2.383M to $2.556M | H29: =_xlfn.MINIFS('All Units'!$R$5:$R$1272,'All Units'!$G$5:$G$1272,$B29,'All Units'!$H$5:$H$1272,$C29) -> 2087100 | I29: =_xlfn.MAXIFS('All Units'!$R$5:$R$1272,'All Units'!$G$5:$G$1272,$B29,'All Units'!$H$5:$H$1272,$C29) -> 2556000
A30: Total 2 Bedroom Premium + Study | B30: 732 / 775 | C30: Both | D30: =SUM(D26:D29) -> 200 | H30: =MIN(H26:H29) -> 1925000 | I30: =MAX(I26:I29) -> 2556000 | J30: 200 | K30: =IF(D30=J30,"Yes","CHECK") -> Yes
A31: 3 Bedroom | B31: 947 | C31: Classic | D31: =COUNTIFS('All Units'!$G$5:$G$1272,$B31,'All Units'!$H$5:$H$1272,$C31) -> 60 | E31: =IF(COUNTIFS('All Units'!$G$5:$G$1272,$B31,'All Units'!$H$5:$H$1272,$C31,'All Units'!$J$5:$J$1272,"Low")=0,"-",TEXT(_xlfn.MINIFS('All Units'!$R$5:$R$1272,'All Units'!$G$5:$G$1272,$B31,'All Units'!$H$5:$H$1272,$C31,'All Units'!$J$5:$J$1272,"Low")/1000000,"$0.000")&"M to "&TEXT(_xlfn.MAXIFS('All Units'!$R$5:$R$1272,'All Units'!$G$5:$G$1272,$B31,'All Units'!$H$5:$H$1272,$C31,'All Units'!$J$5:$J$1272,"Low")/1000000,"$0.000")&"M") -> $2.503M to $2.688M | F31: =IF(COUNTIFS('All Units'!$G$5:$G$1272,$B31,'All Units'!$H$5:$H$1272,$C31,'All Units'!$J$5:$J$1272,"Mid")=0,"-",TEXT(_xlfn.MINIFS('All Units'!$R$5:$R$1272,'All Units'!$G$5:$G$1272,$B31,'All Units'!$H$5:$H$1272,$C31,'All Units'!$J$5:$J$1272,"Mid")/1000000,"$0.000")&"M to "&TEXT(_xlfn.MAXIFS('All Units'!$R$5:$R$1272,'All Units'!$G$5:$G$1272,$B31,'All Units'!$H$5:$H$1272,$C31,'All Units'!$J$5:$J$1272,"Mid")/1000000,"$0.000")&"M") -> $2.601M to $2.814M | G31: =IF(COUNTIFS('All Units'!$G$5:$G$1272,$B31,'All Units'!$H$5:$H$1272,$C31,'All Units'!$J$5:$J$1272,"High")=0,"-",TEXT(_xlfn.MINIFS('All Units'!$R$5:$R$1272,'All Units'!$G$5:$G$1272,$B31,'All Units'!$H$5:$H$1272,$C31,'All Units'!$J$5:$J$1272,"High")/1000000,"$0.000")&"M to "&TEXT(_xlfn.MAXIFS('All Units'!$R$5:$R$1272,'All Units'!$G$5:$G$1272,$B31,'All Units'!$H$5:$H$1272,$C31,'All Units'!$J$5:$J$1272,"High")/1000000,"$0.000")&"M") -> $2.737M to $2.953M | H31: =_xlfn.MINIFS('All Units'!$R$5:$R$1272,'All Units'!$G$5:$G$1272,$B31,'All Units'!$H$5:$H$1272,$C31) -> 2503000 | I31: =_xlfn.MAXIFS('All Units'!$R$5:$R$1272,'All Units'!$G$5:$G$1272,$B31,'All Units'!$H$5:$H$1272,$C31) -> 2952700
A32: 3 Bedroom | B32: 947 | C32: Luxury | D32: =COUNTIFS('All Units'!$G$5:$G$1272,$B32,'All Units'!$H$5:$H$1272,$C32) -> 60 | E32: =IF(COUNTIFS('All Units'!$G$5:$G$1272,$B32,'All Units'!$H$5:$H$1272,$C32,'All Units'!$J$5:$J$1272,"Low")=0,"-",TEXT(_xlfn.MINIFS('All Units'!$R$5:$R$1272,'All Units'!$G$5:$G$1272,$B32,'All Units'!$H$5:$H$1272,$C32,'All Units'!$J$5:$J$1272,"Low")/1000000,"$0.000")&"M to "&TEXT(_xlfn.MAXIFS('All Units'!$R$5:$R$1272,'All Units'!$G$5:$G$1272,$B32,'All Units'!$H$5:$H$1272,$C32,'All Units'!$J$5:$J$1272,"Low")/1000000,"$0.000")&"M") -> $2.598M to $2.814M | F32: =IF(COUNTIFS('All Units'!$G$5:$G$1272,$B32,'All Units'!$H$5:$H$1272,$C32,'All Units'!$J$5:$J$1272,"Mid")=0,"-",TEXT(_xlfn.MINIFS('All Units'!$R$5:$R$1272,'All Units'!$G$5:$G$1272,$B32,'All Units'!$H$5:$H$1272,$C32,'All Units'!$J$5:$J$1272,"Mid")/1000000,"$0.000")&"M to "&TEXT(_xlfn.MAXIFS('All Units'!$R$5:$R$1272,'All Units'!$G$5:$G$1272,$B32,'All Units'!$H$5:$H$1272,$C32,'All Units'!$J$5:$J$1272,"Mid")/1000000,"$0.000")&"M") -> $2.826M to $2.956M | G32: =IF(COUNTIFS('All Units'!$G$5:$G$1272,$B32,'All Units'!$H$5:$H$1272,$C32,'All Units'!$J$5:$J$1272,"High")=0,"-",TEXT(_xlfn.MINIFS('All Units'!$R$5:$R$1272,'All Units'!$G$5:$G$1272,$B32,'All Units'!$H$5:$H$1272,$C32,'All Units'!$J$5:$J$1272,"High")/1000000,"$0.000")&"M to "&TEXT(_xlfn.MAXIFS('All Units'!$R$5:$R$1272,'All Units'!$G$5:$G$1272,$B32,'All Units'!$H$5:$H$1272,$C32,'All Units'!$J$5:$J$1272,"High")/1000000,"$0.000")&"M") -> $2.973M to $3.107M | H32: =_xlfn.MINIFS('All Units'!$R$5:$R$1272,'All Units'!$G$5:$G$1272,$B32,'All Units'!$H$5:$H$1272,$C32) -> 2597600 | I32: =_xlfn.MAXIFS('All Units'!$R$5:$R$1272,'All Units'!$G$5:$G$1272,$B32,'All Units'!$H$5:$H$1272,$C32) -> 3107100
A33: Total 3 Bedroom | B33: 947 | C33: Both | D33: =SUM(D31:D32) -> 120 | H33: =MIN(H31:H32) -> 2503000 | I33: =MAX(I31:I32) -> 3107100 | J33: 120 | K33: =IF(D33=J33,"Yes","CHECK") -> Yes
A34: 3 Bedroom Premium | B34: 1055 | C34: Classic | D34: =COUNTIFS('All Units'!$G$5:$G$1272,$B34,'All Units'!$H$5:$H$1272,$C34) -> 140 | E34: =IF(COUNTIFS('All Units'!$G$5:$G$1272,$B34,'All Units'!$H$5:$H$1272,$C34,'All Units'!$J$5:$J$1272,"Low")=0,"-",TEXT(_xlfn.MINIFS('All Units'!$R$5:$R$1272,'All Units'!$G$5:$G$1272,$B34,'All Units'!$H$5:$H$1272,$C34,'All Units'!$J$5:$J$1272,"Low")/1000000,"$0.000")&"M to "&TEXT(_xlfn.MAXIFS('All Units'!$R$5:$R$1272,'All Units'!$G$5:$G$1272,$B34,'All Units'!$H$5:$H$1272,$C34,'All Units'!$J$5:$J$1272,"Low")/1000000,"$0.000")&"M") -> $2.777M to $2.956M | F34: =IF(COUNTIFS('All Units'!$G$5:$G$1272,$B34,'All Units'!$H$5:$H$1272,$C34,'All Units'!$J$5:$J$1272,"Mid")=0,"-",TEXT(_xlfn.MINIFS('All Units'!$R$5:$R$1272,'All Units'!$G$5:$G$1272,$B34,'All Units'!$H$5:$H$1272,$C34,'All Units'!$J$5:$J$1272,"Mid")/1000000,"$0.000")&"M to "&TEXT(_xlfn.MAXIFS('All Units'!$R$5:$R$1272,'All Units'!$G$5:$G$1272,$B34,'All Units'!$H$5:$H$1272,$C34,'All Units'!$J$5:$J$1272,"Mid")/1000000,"$0.000")&"M") -> $2.875M to $3.121M | G34: =IF(COUNTIFS('All Units'!$G$5:$G$1272,$B34,'All Units'!$H$5:$H$1272,$C34,'All Units'!$J$5:$J$1272,"High")=0,"-",TEXT(_xlfn.MINIFS('All Units'!$R$5:$R$1272,'All Units'!$G$5:$G$1272,$B34,'All Units'!$H$5:$H$1272,$C34,'All Units'!$J$5:$J$1272,"High")/1000000,"$0.000")&"M to "&TEXT(_xlfn.MAXIFS('All Units'!$R$5:$R$1272,'All Units'!$G$5:$G$1272,$B34,'All Units'!$H$5:$H$1272,$C34,'All Units'!$J$5:$J$1272,"High")/1000000,"$0.000")&"M") -> $3.049M to $3.260M | H34: =_xlfn.MINIFS('All Units'!$R$5:$R$1272,'All Units'!$G$5:$G$1272,$B34,'All Units'!$H$5:$H$1272,$C34) -> 2777000 | I34: =_xlfn.MAXIFS('All Units'!$R$5:$R$1272,'All Units'!$G$5:$G$1272,$B34,'All Units'!$H$5:$H$1272,$C34) -> 3260000
A35: 3 Bedroom Premium | B35: 1055 | C35: Luxury | D35: =COUNTIFS('All Units'!$G$5:$G$1272,$B35,'All Units'!$H$5:$H$1272,$C35) -> 30 | E35: =IF(COUNTIFS('All Units'!$G$5:$G$1272,$B35,'All Units'!$H$5:$H$1272,$C35,'All Units'!$J$5:$J$1272,"Low")=0,"-",TEXT(_xlfn.MINIFS('All Units'!$R$5:$R$1272,'All Units'!$G$5:$G$1272,$B35,'All Units'!$H$5:$H$1272,$C35,'All Units'!$J$5:$J$1272,"Low")/1000000,"$0.000")&"M to "&TEXT(_xlfn.MAXIFS('All Units'!$R$5:$R$1272,'All Units'!$G$5:$G$1272,$B35,'All Units'!$H$5:$H$1272,$C35,'All Units'!$J$5:$J$1272,"Low")/1000000,"$0.000")&"M") -> $2.929M to $3.085M | F35: =IF(COUNTIFS('All Units'!$G$5:$G$1272,$B35,'All Units'!$H$5:$H$1272,$C35,'All Units'!$J$5:$J$1272,"Mid")=0,"-",TEXT(_xlfn.MINIFS('All Units'!$R$5:$R$1272,'All Units'!$G$5:$G$1272,$B35,'All Units'!$H$5:$H$1272,$C35,'All Units'!$J$5:$J$1272,"Mid")/1000000,"$0.000")&"M to "&TEXT(_xlfn.MAXIFS('All Units'!$R$5:$R$1272,'All Units'!$G$5:$G$1272,$B35,'All Units'!$H$5:$H$1272,$C35,'All Units'!$J$5:$J$1272,"Mid")/1000000,"$0.000")&"M") -> $3.101M to $3.261M | G35: =IF(COUNTIFS('All Units'!$G$5:$G$1272,$B35,'All Units'!$H$5:$H$1272,$C35,'All Units'!$J$5:$J$1272,"High")=0,"-",TEXT(_xlfn.MINIFS('All Units'!$R$5:$R$1272,'All Units'!$G$5:$G$1272,$B35,'All Units'!$H$5:$H$1272,$C35,'All Units'!$J$5:$J$1272,"High")/1000000,"$0.000")&"M to "&TEXT(_xlfn.MAXIFS('All Units'!$R$5:$R$1272,'All Units'!$G$5:$G$1272,$B35,'All Units'!$H$5:$H$1272,$C35,'All Units'!$J$5:$J$1272,"High")/1000000,"$0.000")&"M") -> $3.282M to $3.433M | H35: =_xlfn.MINIFS('All Units'!$R$5:$R$1272,'All Units'!$G$5:$G$1272,$B35,'All Units'!$H$5:$H$1272,$C35) -> 2928700 | I35: =_xlfn.MAXIFS('All Units'!$R$5:$R$1272,'All Units'!$G$5:$G$1272,$B35,'All Units'!$H$5:$H$1272,$C35) -> 3433000
A36: Total 3 Bedroom Premium | B36: 1,055 | C36: Both | D36: =SUM(D34:D35) -> 170 | H36: =MIN(H34:H35) -> 2777000 | I36: =MAX(I34:I35) -> 3433000 | J36: 170 | K36: =IF(D36=J36,"Yes","CHECK") -> Yes
A37: 3 Bedroom Premium + Study | B37: 1152 | C37: Classic | D37: =COUNTIFS('All Units'!$G$5:$G$1272,$B37,'All Units'!$H$5:$H$1272,$C37) -> 60 | E37: =IF(COUNTIFS('All Units'!$G$5:$G$1272,$B37,'All Units'!$H$5:$H$1272,$C37,'All Units'!$J$5:$J$1272,"Low")=0,"-",TEXT(_xlfn.MINIFS('All Units'!$R$5:$R$1272,'All Units'!$G$5:$G$1272,$B37,'All Units'!$H$5:$H$1272,$C37,'All Units'!$J$5:$J$1272,"Low")/1000000,"$0.000")&"M to "&TEXT(_xlfn.MAXIFS('All Units'!$R$5:$R$1272,'All Units'!$G$5:$G$1272,$B37,'All Units'!$H$5:$H$1272,$C37,'All Units'!$J$5:$J$1272,"Low")/1000000,"$0.000")&"M") -> $3.053M to $3.235M | F37: =IF(COUNTIFS('All Units'!$G$5:$G$1272,$B37,'All Units'!$H$5:$H$1272,$C37,'All Units'!$J$5:$J$1272,"Mid")=0,"-",TEXT(_xlfn.MINIFS('All Units'!$R$5:$R$1272,'All Units'!$G$5:$G$1272,$B37,'All Units'!$H$5:$H$1272,$C37,'All Units'!$J$5:$J$1272,"Mid")/1000000,"$0.000")&"M to "&TEXT(_xlfn.MAXIFS('All Units'!$R$5:$R$1272,'All Units'!$G$5:$G$1272,$B37,'All Units'!$H$5:$H$1272,$C37,'All Units'!$J$5:$J$1272,"Mid")/1000000,"$0.000")&"M") -> $3.165M to $3.396M | G37: =IF(COUNTIFS('All Units'!$G$5:$G$1272,$B37,'All Units'!$H$5:$H$1272,$C37,'All Units'!$J$5:$J$1272,"High")=0,"-",TEXT(_xlfn.MINIFS('All Units'!$R$5:$R$1272,'All Units'!$G$5:$G$1272,$B37,'All Units'!$H$5:$H$1272,$C37,'All Units'!$J$5:$J$1272,"High")/1000000,"$0.000")&"M to "&TEXT(_xlfn.MAXIFS('All Units'!$R$5:$R$1272,'All Units'!$G$5:$G$1272,$B37,'All Units'!$H$5:$H$1272,$C37,'All Units'!$J$5:$J$1272,"High")/1000000,"$0.000")&"M") -> $3.324M to $3.562M | H37: =_xlfn.MINIFS('All Units'!$R$5:$R$1272,'All Units'!$G$5:$G$1272,$B37,'All Units'!$H$5:$H$1272,$C37) -> 3052800 | I37: =_xlfn.MAXIFS('All Units'!$R$5:$R$1272,'All Units'!$G$5:$G$1272,$B37,'All Units'!$H$5:$H$1272,$C37) -> 3562000
A38: Total 3 Bedroom Premium + Study | B38: 1,152 | D38: =SUM(D37:D37) -> 60 | H38: =MIN(H37:H37) -> 3052800 | I38: =MAX(I37:I37) -> 3562000 | J38: 60 | K38: =IF(D38=J38,"Yes","CHECK") -> Yes
A39: 4 Bedroom | B39: 1238 | C39: Classic | D39: =COUNTIFS('All Units'!$G$5:$G$1272,$B39,'All Units'!$H$5:$H$1272,$C39) -> 60 | E39: =IF(COUNTIFS('All Units'!$G$5:$G$1272,$B39,'All Units'!$H$5:$H$1272,$C39,'All Units'!$J$5:$J$1272,"Low")=0,"-",TEXT(_xlfn.MINIFS('All Units'!$R$5:$R$1272,'All Units'!$G$5:$G$1272,$B39,'All Units'!$H$5:$H$1272,$C39,'All Units'!$J$5:$J$1272,"Low")/1000000,"$0.000")&"M to "&TEXT(_xlfn.MAXIFS('All Units'!$R$5:$R$1272,'All Units'!$G$5:$G$1272,$B39,'All Units'!$H$5:$H$1272,$C39,'All Units'!$J$5:$J$1272,"Low")/1000000,"$0.000")&"M") -> $3.388M to $3.533M | F39: =IF(COUNTIFS('All Units'!$G$5:$G$1272,$B39,'All Units'!$H$5:$H$1272,$C39,'All Units'!$J$5:$J$1272,"Mid")=0,"-",TEXT(_xlfn.MINIFS('All Units'!$R$5:$R$1272,'All Units'!$G$5:$G$1272,$B39,'All Units'!$H$5:$H$1272,$C39,'All Units'!$J$5:$J$1272,"Mid")/1000000,"$0.000")&"M to "&TEXT(_xlfn.MAXIFS('All Units'!$R$5:$R$1272,'All Units'!$G$5:$G$1272,$B39,'All Units'!$H$5:$H$1272,$C39,'All Units'!$J$5:$J$1272,"Mid")/1000000,"$0.000")&"M") -> $3.443M to $3.678M | G39: =IF(COUNTIFS('All Units'!$G$5:$G$1272,$B39,'All Units'!$H$5:$H$1272,$C39,'All Units'!$J$5:$J$1272,"High")=0,"-",TEXT(_xlfn.MINIFS('All Units'!$R$5:$R$1272,'All Units'!$G$5:$G$1272,$B39,'All Units'!$H$5:$H$1272,$C39,'All Units'!$J$5:$J$1272,"High")/1000000,"$0.000")&"M to "&TEXT(_xlfn.MAXIFS('All Units'!$R$5:$R$1272,'All Units'!$G$5:$G$1272,$B39,'All Units'!$H$5:$H$1272,$C39,'All Units'!$J$5:$J$1272,"High")/1000000,"$0.000")&"M") -> $3.608M to $3.854M | H39: =_xlfn.MINIFS('All Units'!$R$5:$R$1272,'All Units'!$G$5:$G$1272,$B39,'All Units'!$H$5:$H$1272,$C39) -> 3388000 | I39: =_xlfn.MAXIFS('All Units'!$R$5:$R$1272,'All Units'!$G$5:$G$1272,$B39,'All Units'!$H$5:$H$1272,$C39) -> 3853900
A40: 4 Bedroom | B40: 1238 | C40: Luxury | D40: =COUNTIFS('All Units'!$G$5:$G$1272,$B40,'All Units'!$H$5:$H$1272,$C40) -> 30 | E40: =IF(COUNTIFS('All Units'!$G$5:$G$1272,$B40,'All Units'!$H$5:$H$1272,$C40,'All Units'!$J$5:$J$1272,"Low")=0,"-",TEXT(_xlfn.MINIFS('All Units'!$R$5:$R$1272,'All Units'!$G$5:$G$1272,$B40,'All Units'!$H$5:$H$1272,$C40,'All Units'!$J$5:$J$1272,"Low")/1000000,"$0.000")&"M to "&TEXT(_xlfn.MAXIFS('All Units'!$R$5:$R$1272,'All Units'!$G$5:$G$1272,$B40,'All Units'!$H$5:$H$1272,$C40,'All Units'!$J$5:$J$1272,"Low")/1000000,"$0.000")&"M") -> $3.497M to $3.665M | F40: =IF(COUNTIFS('All Units'!$G$5:$G$1272,$B40,'All Units'!$H$5:$H$1272,$C40,'All Units'!$J$5:$J$1272,"Mid")=0,"-",TEXT(_xlfn.MINIFS('All Units'!$R$5:$R$1272,'All Units'!$G$5:$G$1272,$B40,'All Units'!$H$5:$H$1272,$C40,'All Units'!$J$5:$J$1272,"Mid")/1000000,"$0.000")&"M to "&TEXT(_xlfn.MAXIFS('All Units'!$R$5:$R$1272,'All Units'!$G$5:$G$1272,$B40,'All Units'!$H$5:$H$1272,$C40,'All Units'!$J$5:$J$1272,"Mid")/1000000,"$0.000")&"M") -> $3.681M to $3.853M | G40: =IF(COUNTIFS('All Units'!$G$5:$G$1272,$B40,'All Units'!$H$5:$H$1272,$C40,'All Units'!$J$5:$J$1272,"High")=0,"-",TEXT(_xlfn.MINIFS('All Units'!$R$5:$R$1272,'All Units'!$G$5:$G$1272,$B40,'All Units'!$H$5:$H$1272,$C40,'All Units'!$J$5:$J$1272,"High")/1000000,"$0.000")&"M to "&TEXT(_xlfn.MAXIFS('All Units'!$R$5:$R$1272,'All Units'!$G$5:$G$1272,$B40,'All Units'!$H$5:$H$1272,$C40,'All Units'!$J$5:$J$1272,"High")/1000000,"$0.000")&"M") -> $3.880M to $4.124M | H40: =_xlfn.MINIFS('All Units'!$R$5:$R$1272,'All Units'!$G$5:$G$1272,$B40,'All Units'!$H$5:$H$1272,$C40) -> 3497400 | I40: =_xlfn.MAXIFS('All Units'!$R$5:$R$1272,'All Units'!$G$5:$G$1272,$B40,'All Units'!$H$5:$H$1272,$C40) -> 4123800
A41: Total 4 Bedroom | B41: 1,238 | C41: Both | D41: =SUM(D39:D40) -> 90 | H41: =MIN(H39:H40) -> 3388000 | I41: =MAX(I39:I40) -> 4123800 | J41: 90 | K41: =IF(D41=J41,"Yes","CHECK") -> Yes
A42: 4 Bedroom Premium (w Private Lift) | B42: 1367 | C42: Luxury | D42: =COUNTIFS('All Units'!$G$5:$G$1272,$B42,'All Units'!$H$5:$H$1272,$C42) -> 56 | E42: =IF(COUNTIFS('All Units'!$G$5:$G$1272,$B42,'All Units'!$H$5:$H$1272,$C42,'All Units'!$J$5:$J$1272,"Low")=0,"-",TEXT(_xlfn.MINIFS('All Units'!$R$5:$R$1272,'All Units'!$G$5:$G$1272,$B42,'All Units'!$H$5:$H$1272,$C42,'All Units'!$J$5:$J$1272,"Low")/1000000,"$0.000")&"M to "&TEXT(_xlfn.MAXIFS('All Units'!$R$5:$R$1272,'All Units'!$G$5:$G$1272,$B42,'All Units'!$H$5:$H$1272,$C42,'All Units'!$J$5:$J$1272,"Low")/1000000,"$0.000")&"M") -> $3.828M to $4.085M | F42: =IF(COUNTIFS('All Units'!$G$5:$G$1272,$B42,'All Units'!$H$5:$H$1272,$C42,'All Units'!$J$5:$J$1272,"Mid")=0,"-",TEXT(_xlfn.MINIFS('All Units'!$R$5:$R$1272,'All Units'!$G$5:$G$1272,$B42,'All Units'!$H$5:$H$1272,$C42,'All Units'!$J$5:$J$1272,"Mid")/1000000,"$0.000")&"M to "&TEXT(_xlfn.MAXIFS('All Units'!$R$5:$R$1272,'All Units'!$G$5:$G$1272,$B42,'All Units'!$H$5:$H$1272,$C42,'All Units'!$J$5:$J$1272,"Mid")/1000000,"$0.000")&"M") -> $3.999M to $4.225M | G42: =IF(COUNTIFS('All Units'!$G$5:$G$1272,$B42,'All Units'!$H$5:$H$1272,$C42,'All Units'!$J$5:$J$1272,"High")=0,"-",TEXT(_xlfn.MINIFS('All Units'!$R$5:$R$1272,'All Units'!$G$5:$G$1272,$B42,'All Units'!$H$5:$H$1272,$C42,'All Units'!$J$5:$J$1272,"High")/1000000,"$0.000")&"M to "&TEXT(_xlfn.MAXIFS('All Units'!$R$5:$R$1272,'All Units'!$G$5:$G$1272,$B42,'All Units'!$H$5:$H$1272,$C42,'All Units'!$J$5:$J$1272,"High")/1000000,"$0.000")&"M") -> $4.161M to $4.588M | H42: =_xlfn.MINIFS('All Units'!$R$5:$R$1272,'All Units'!$G$5:$G$1272,$B42,'All Units'!$H$5:$H$1272,$C42) -> 3827600 | I42: =_xlfn.MAXIFS('All Units'!$R$5:$R$1272,'All Units'!$G$5:$G$1272,$B42,'All Units'!$H$5:$H$1272,$C42) -> 4587700
...

Sheet All Units
A1: Thomson Reserve: All Units (1,268), indicative pricing
A2: Est. PSF = Floor curve PSF (project chief guide) + Stack position (up to +/- $50K, ranked by view), never below the developer starting PSF and never below the floor beneath it. Filter to build a client shortlist.
A4: Unit no. | B4: Blk | C4: Stack | D4: Level | E4: Unit type | F4: Type (floor plan) | G4: Size (sqft) | H4: Collection | I4: Tier | J4: Floor band (guide) | K4: Starting PSF | L4: Floor curve PSF | M4: Stack position $ | N4: Stack position PSF | O4: Curve + position PSF | P4: Premium stage | Q4: Est. PSF | R4: Est. price | S4: Flags | T4: Facing & view
A5: #21-01 | B5: 1 | C5: 1 | D5: 21 | E5: 3 Bedroom Premium | F5: CP2 | G5: 1055 | H5: Classic | I5: =Assumptions!$I$127 -> C | J5: =IF(D5<=Assumptions!$V$127,"Low",IF(D5<=Assumptions!$W$127,"Mid","High")) -> High | K5: =Assumptions!$Q$127 -> 2633 | L5: =INDEX(Assumptions!$K$61:$K$90,D5) -> 3042.1538 | M5: =IF(D5<=Assumptions!$G$127,Assumptions!$AK$127,IF(D5<Assumptions!$AH$127,Assumptions!$AK$127+(Assumptions!$AL$127-Assumptions!$AK$127)*(D5-Assumptions!$G$127)/(Assumptions!$AH$127-Assumptions!$G$127),IF(D5<Assumptions!$P$127,Assumptions!$AL$127+(Assumptions!$AM$127-Assumptions!$AL$127)*(D5-Assumptions!$AH$127)/(Assumptions!$P$127-Assumptions!$AH$127),Assumptions!$AM$127))) -> 50000 | N5: =M5/G5 -> 47.393365 | O5: =ROUND(L5+N5,0) -> 3090 | P5: =IF(D5>=Assumptions!$P$127,"High",IF(D5>=Assumptions!$AH$127,"Mid",IF(D5<=Assumptions!$G$127,"Low","Loading"))) -> High | Q5: =MAX(K5,MIN(Assumptions!$S$127,O5),Q6) -> 3090 | R5: =IF(AND(Q5<=K5,INDEX(Assumptions!$C$26:$C$36,MATCH(G5,Assumptions!$A$26:$A$36,0))<>""),INDEX(Assumptions!$C$26:$C$36,MATCH(G5,Assumptions!$A$26:$A$36,0)),ROUND(G5*Q5,-2)) -> 3260000 | S5: =TRIM(IF(AND(Assumptions!$L$127<>"",D5<Assumptions!$L$127),"View blocked / roof in front ("&Assumptions!$M$127&"); view premium still loading until L"&Assumptions!$L$127&". ","")&IF(D5=Assumptions!$AH$127,"Mid-floor view premium fully loaded. ","")&IF(D5=Assumptions!$P$127,"High-floor view premium fully loaded. ","")&IF(Q5<=K5,"At developer starting price.","")) | T5: =Assumptions!$AJ$127 -> SSE. Unblocked landed estate + nature reserve + city; MacRitchie Reservoir Park unblocked from mid floor; road noise on low floors. Tier C: below pool-facing 06/18 on low floors, dearer than them on high floors
A6: #20-01 | B6: 1 | C6: 1 | D6: 20 | E6: 3 Bedroom Premium | F6: CP2 | G6: 1055 | H6: Classic | I6: =Assumptions!$I$127 -> C | J6: =IF(D6<=Assumptions!$V$127,"Low",IF(D6<=Assumptions!$W$127,"Mid","High")) -> High | K6: =Assumptions!$Q$127 -> 2633 | L6: =INDEX(Assumptions!$K$61:$K$90,D6) -> 3015.8769 | M6: =IF(D6<=Assumptions!$G$127,Assumptions!$AK$127,IF(D6<Assumptions!$AH$127,Assumptions!$AK$127+(Assumptions!$AL$127-Assumptions!$AK$127)*(D6-Assumptions!$G$127)/(Assumptions!$AH$127-Assumptions!$G$127),IF(D6<Assumptions!$P$127,Assumptions!$AL$127+(Assumptions!$AM$127-Assumptions!$AL$127)*(D6-Assumptions!$AH$127)/(Assumptions!$P$127-Assumptions!$AH$127),Assumptions!$AM$127))) -> 50000 | N6: =M6/G6 -> 47.393365 | O6: =ROUND(L6+N6,0) -> 3063 | P6: =IF(D6>=Assumptions!$P$127,"High",IF(D6>=Assumptions!$AH$127,"Mid",IF(D6<=Assumptions!$G$127,"Low","Loading"))) -> High | Q6: =MAX(K6,MIN(Assumptions!$S$127,O6),Q7) -> 3063 | R6: =IF(AND(Q6<=K6,INDEX(Assumptions!$C$26:$C$36,MATCH(G6,Assumptions!$A$26:$A$36,0))<>""),INDEX(Assumptions!$C$26:$C$36,MATCH(G6,Assumptions!$A$26:$A$36,0)),ROUND(G6*Q6,-2)) -> 3231500 | S6: =TRIM(IF(AND(Assumptions!$L$127<>"",D6<Assumptions!$L$127),"View blocked / roof in front ("&Assumptions!$M$127&"); view premium still loading until L"&Assumptions!$L$127&". ","")&IF(D6=Assumptions!$AH$127,"Mid-floor view premium fully loaded. ","")&IF(D6=Assumptions!$P$127,"High-floor view premium fully loaded. ","")&IF(Q6<=K6,"At developer starting price.","")) | T6: =Assumptions!$AJ$127 -> SSE. Unblocked landed estate + nature reserve + city; MacRitchie Reservoir Park unblocked from mid floor; road noise on low floors. Tier C: below pool-facing 06/18 on low floors, dearer than them on high floors
A7: #19-01 | B7: 1 | C7: 1 | D7: 19 | E7: 3 Bedroom Premium | F7: CP2 | G7: 1055 | H7: Classic | I7: =Assumptions!$I$127 -> C | J7: =IF(D7<=Assumptions!$V$127,"Low",IF(D7<=Assumptions!$W$127,"Mid","High")) -> High | K7: =Assumptions!$Q$127 -> 2633 | L7: =INDEX(Assumptions!$K$61:$K$90,D7) -> 2989.6 | M7: =IF(D7<=Assumptions!$G$127,Assumptions!$AK$127,IF(D7<Assumptions!$AH$127,Assumptions!$AK$127+(Assumptions!$AL$127-Assumptions!$AK$127)*(D7-Assumptions!$G$127)/(Assumptions!$AH$127-Assumptions!$G$127),IF(D7<Assumptions!$P$127,Assumptions!$AL$127+(Assumptions!$AM$127-Assumptions!$AL$127)*(D7-Assumptions!$AH$127)/(Assumptions!$P$127-Assumptions!$AH$127),Assumptions!$AM$127))) -> 50000 | N7: =M7/G7 -> 47.393365 | O7: =ROUND(L7+N7,0) -> 3037 | P7: =IF(D7>=Assumptions!$P$127,"High",IF(D7>=Assumptions!$AH$127,"Mid",IF(D7<=Assumptions!$G$127,"Low","Loading"))) -> High | Q7: =MAX(K7,MIN(Assumptions!$S$127,O7),Q8) -> 3037 | R7: =IF(AND(Q7<=K7,INDEX(Assumptions!$C$26:$C$36,MATCH(G7,Assumptions!$A$26:$A$36,0))<>""),INDEX(Assumptions!$C$26:$C$36,MATCH(G7,Assumptions!$A$26:$A$36,0)),ROUND(G7*Q7,-2)) -> 3204000 | S7: =TRIM(IF(AND(Assumptions!$L$127<>"",D7<Assumptions!$L$127),"View blocked / roof in front ("&Assumptions!$M$127&"); view premium still loading until L"&Assumptions!$L$127&". ","")&IF(D7=Assumptions!$AH$127,"Mid-floor view premium fully loaded. ","")&IF(D7=Assumptions!$P$127,"High-floor view premium fully loaded. ","")&IF(Q7<=K7,"At developer starting price.","")) | T7: =Assumptions!$AJ$127 -> SSE. Unblocked landed estate + nature reserve + city; MacRitchie Reservoir Park unblocked from mid floor; road noise on low floors. Tier C: below pool-facing 06/18 on low floors, dearer than them on high floors
A8: #18-01 | B8: 1 | C8: 1 | D8: 18 | E8: 3 Bedroom Premium | F8: CP2 | G8: 1055 | H8: Classic | I8: =Assumptions!$I$127 -> C | J8: =IF(D8<=Assumptions!$V$127,"Low",IF(D8<=Assumptions!$W$127,"Mid","High")) -> High | K8: =Assumptions!$Q$127 -> 2633 | L8: =INDEX(Assumptions!$K$61:$K$90,D8) -> 2963.3231 | M8: =IF(D8<=Assumptions!$G$127,Assumptions!$AK$127,IF(D8<Assumptions!$AH$127,Assumptions!$AK$127+(Assumptions!$AL$127-Assumptions!$AK$127)*(D8-Assumptions!$G$127)/(Assumptions!$AH$127-Assumptions!$G$127),IF(D8<Assumptions!$P$127,Assumptions!$AL$127+(Assumptions!$AM$127-Assumptions!$AL$127)*(D8-Assumptions!$AH$127)/(Assumptions!$P$127-Assumptions!$AH$127),Assumptions!$AM$127))) -> 50000 | N8: =M8/G8 -> 47.393365 | O8: =ROUND(L8+N8,0) -> 3011 | P8: =IF(D8>=Assumptions!$P$127,"High",IF(D8>=Assumptions!$AH$127,"Mid",IF(D8<=Assumptions!$G$127,"Low","Loading"))) -> High | Q8: =MAX(K8,MIN(Assumptions!$S$127,O8),Q9) -> 3011 | R8: =IF(AND(Q8<=K8,INDEX(Assumptions!$C$26:$C$36,MATCH(G8,Assumptions!$A$26:$A$36,0))<>""),INDEX(Assumptions!$C$26:$C$36,MATCH(G8,Assumptions!$A$26:$A$36,0)),ROUND(G8*Q8,-2)) -> 3176600 | S8: =TRIM(IF(AND(Assumptions!$L$127<>"",D8<Assumptions!$L$127),"View blocked / roof in front ("&Assumptions!$M$127&"); view premium still loading until L"&Assumptions!$L$127&". ","")&IF(D8=Assumptions!$AH$127,"Mid-floor view premium fully loaded. ","")&IF(D8=Assumptions!$P$127,"High-floor view premium fully loaded. ","")&IF(Q8<=K8,"At developer starting price.","")) | T8: =Assumptions!$AJ$127 -> SSE. Unblocked landed estate + nature reserve + city; MacRitchie Reservoir Park unblocked from mid floor; road noise on low floors. Tier C: below pool-facing 06/18 on low floors, dearer than them on high floors
A9: #17-01 | B9: 1 | C9: 1 | D9: 17 | E9: 3 Bedroom Premium | F9: CP2 | G9: 1055 | H9: Classic | I9: =Assumptions!$I$127 -> C | J9: =IF(D9<=Assumptions!$V$127,"Low",IF(D9<=Assumptions!$W$127,"Mid","High")) -> High | K9: =Assumptions!$Q$127 -> 2633 | L9: =INDEX(Assumptions!$K$61:$K$90,D9) -> 2937.0462 | M9: =IF(D9<=Assumptions!$G$127,Assumptions!$AK$127,IF(D9<Assumptions!$AH$127,Assumptions!$AK$127+(Assumptions!$AL$127-Assumptions!$AK$127)*(D9-Assumptions!$G$127)/(Assumptions!$AH$127-Assumptions!$G$127),IF(D9<Assumptions!$P$127,Assumptions!$AL$127+(Assumptions!$AM$127-Assumptions!$AL$127)*(D9-Assumptions!$AH$127)/(Assumptions!$P$127-Assumptions!$AH$127),Assumptions!$AM$127))) -> 50000 | N9: =M9/G9 -> 47.393365 | O9: =ROUND(L9+N9,0) -> 2984 | P9: =IF(D9>=Assumptions!$P$127,"High",IF(D9>=Assumptions!$AH$127,"Mid",IF(D9<=Assumptions!$G$127,"Low","Loading"))) -> High | Q9: =MAX(K9,MIN(Assumptions!$S$127,O9),Q10) -> 2984 | R9: =IF(AND(Q9<=K9,INDEX(Assumptions!$C$26:$C$36,MATCH(G9,Assumptions!$A$26:$A$36,0))<>""),INDEX(Assumptions!$C$26:$C$36,MATCH(G9,Assumptions!$A$26:$A$36,0)),ROUND(G9*Q9,-2)) -> 3148100 | S9: =TRIM(IF(AND(Assumptions!$L$127<>"",D9<Assumptions!$L$127),"View blocked / roof in front ("&Assumptions!$M$127&"); view premium still loading until L"&Assumptions!$L$127&". ","")&IF(D9=Assumptions!$AH$127,"Mid-floor view premium fully loaded. ","")&IF(D9=Assumptions!$P$127,"High-floor view premium fully loaded. ","")&IF(Q9<=K9,"At developer starting price.","")) -> High-floor view premium fully loaded. | T9: =Assumptions!$AJ$127 -> SSE. Unblocked landed estate + nature reserve + city; MacRitchie Reservoir Park unblocked from mid floor; road noise on low floors. Tier C: below pool-facing 06/18 on low floors, dearer than them on high floors
A10: #16-01 | B10: 1 | C10: 1 | D10: 16 | E10: 3 Bedroom Premium | F10: CP2 | G10: 1055 | H10: Classic | I10: =Assumptions!$I$127 -> C | J10: =IF(D10<=Assumptions!$V$127,"Low",IF(D10<=Assumptions!$W$127,"Mid","High")) -> Mid | K10: =Assumptions!$Q$127 -> 2633 | L10: =INDEX(Assumptions!$K$61:$K$90,D10) -> 2910.7692 | M10: =IF(D10<=Assumptions!$G$127,Assumptions!$AK$127,IF(D10<Assumptions!$AH$127,Assumptions!$AK$127+(Assumptions!$AL$127-Assumptions!$AK$127)*(D10-Assumptions!$G$127)/(Assumptions!$AH$127-Assumptions!$G$127),IF(D10<Assumptions!$P$127,Assumptions!$AL$127+(Assumptions!$AM$127-Assumptions!$AL$127)*(D10-Assumptions!$AH$127)/(Assumptions!$P$127-Assumptions!$AH$127),Assumptions!$AM$127))) -> 50000 | N10: =M10/G10 -> 47.393365 | O10: =ROUND(L10+N10,0) -> 2958 | P10: =IF(D10>=Assumptions!$P$127,"High",IF(D10>=Assumptions!$AH$127,"Mid",IF(D10<=Assumptions!$G$127,"Low","Loading"))) -> Mid | Q10: =MAX(K10,MIN(Assumptions!$S$127,O10),Q11) -> 2958 | R10: =IF(AND(Q10<=K10,INDEX(Assumptions!$C$26:$C$36,MATCH(G10,Assumptions!$A$26:$A$36,0))<>""),INDEX(Assumptions!$C$26:$C$36,MATCH(G10,Assumptions!$A$26:$A$36,0)),ROUND(G10*Q10,-2)) -> 3120700 | S10: =TRIM(IF(AND(Assumptions!$L$127<>"",D10<Assumptions!$L$127),"View blocked / roof in front ("&Assumptions!$M$127&"); view premium still loading until L"&Assumptions!$L$127&". ","")&IF(D10=Assumptions!$AH$127,"Mid-floor view premium fully loaded. ","")&IF(D10=Assumptions!$P$127,"High-floor view premium fully loaded. ","")&IF(Q10<=K10,"At developer starting price.","")) | T10: =Assumptions!$AJ$127 -> SSE. Unblocked landed estate + nature reserve + city; MacRitchie Reservoir Park unblocked from mid floor; road noise on low floors. Tier C: below pool-facing 06/18 on low floors, dearer than them on high floors
